const axios = require('axios');

async function testErrorBoundary() {
  console.log('🔧 测试错误边界 - 方案1实施\n');
  
  try {
    // 1. 检查前端服务
    console.log('1️⃣ 检查前端服务...');
    const frontendResponse = await axios.get('http://localhost:3000/');
    console.log('✅ 前端服务正常');
    
    // 2. 等待编译完成
    console.log('\n2️⃣ 等待编译完成...');
    await new Promise(resolve => setTimeout(resolve, 5000));
    
    // 3. 检查JavaScript bundle
    console.log('\n3️⃣ 检查JavaScript bundle...');
    try {
      const bundleResponse = await axios.get('http://localhost:3000/static/js/bundle.js');
      console.log('✅ JavaScript bundle可访问');
      console.log('Bundle大小:', (bundleResponse.data.length / 1024 / 1024).toFixed(2), 'MB');
      
      // 检查是否包含错误边界代码
      const hasErrorBoundary = bundleResponse.data.includes('ErrorBoundary') && 
                              bundleResponse.data.includes('componentDidCatch');
      console.log('包含错误边界代码:', hasErrorBoundary ? '✅ 是' : '❌ 否');
      
      if (hasErrorBoundary) {
        console.log('🎉 太好了！错误边界已经成功添加！');
      }
      
    } catch (error) {
      console.log('❌ JavaScript bundle不可访问');
    }
    
    console.log('\n🎯 现在请按照以下步骤操作：');
    
    console.log('\n1️⃣ 访问页面：');
    console.log('   - 访问：http://localhost:3000/#/admin');
    console.log('   - 使用登录信息：知行 / Zhixing Universal Trading Signal');
    
    console.log('\n2️⃣ 观察结果：');
    console.log('   - 如果AdminOverview组件出错，现在会显示详细的错误信息');
    console.log('   - 错误信息会包含错误名称、消息和堆栈信息');
    console.log('   - 不会出现白板，而是显示错误详情');
    
    console.log('\n3️⃣ 如果看到错误信息：');
    console.log('   - 请告诉我具体的错误名称和消息');
    console.log('   - 这样我们就能准确定位问题所在');
    console.log('   - 然后针对性地修复问题');
    
    console.log('\n🔍 预期结果：');
    console.log('1. 如果组件正常：显示数据概览页面');
    console.log('2. 如果组件出错：显示详细的错误信息框');
    console.log('3. 不会再有白板或闪退问题');
    
    console.log('\n💡 如果还是有问题，请告诉我：');
    console.log('1. 是否看到了错误信息框？');
    console.log('2. 错误信息的具体内容是什么？');
    console.log('3. 是否还有闪退问题？');
    
    console.log('\n🎉 现在错误边界已经添加，应该能捕获到具体的错误信息了！');
    
  } catch (error) {
    console.error('❌ 测试失败:', error.message);
  }
}

testErrorBoundary(); 